<?xml version="1.0" ?>
<sdf version="1.7">
  <model name="bolitabot">
    <pose>0 0 0 0 0 0</pose>
    <static>false</static>

    <!-- Chasis -->
    <link name="chassis">
      <pose>0 0 0.25 0 0 0</pose>
      <inertial>
        <mass>5.0</mass>
        <inertia>
          <ixx>0.1</ixx><iyy>0.1</iyy><izz>0.1</izz>
        </inertia>
      </inertial>
      <visual name="visual">
        <geometry>
          <box><size>1.5 1.0 0.05</size></box>
        </geometry>
        <material>
          <ambient>1 0.5 0 1</ambient>
          <diffuse>1 0.5 0 1</diffuse>
        </material>
      </visual>
      <collision name="collision">
        <geometry>
          <box><size>1.5 1.0 0.1</size></box>
        </geometry>
      </collision>
    </link>

    <!-- Rueda izquierda -->
    <link name="left_wheel">
      <pose>0 0.7 0.18 1.57 0 0</pose>
      <inertial>
        <mass>0.5</mass>
        <inertia>
          <ixx>0.01</ixx><iyy>0.01</iyy><izz>0.01</izz>
        </inertia>
      </inertial>
      <collision name="collision">
        <geometry>
          <cylinder><radius>0.2</radius><length>0.2</length></cylinder>
        </geometry>
        <surface>
          <friction>
            <ode><mu>5.0</mu><mu2>5.0</mu2></ode>
          </friction>
        </surface>
      </collision>
      <visual name="visual">
        <geometry>
          <cylinder><radius>0.2</radius><length>0.2</length></cylinder>
        </geometry>
        <material>
          <ambient>0.1 0.1 0.1 1</ambient>
          <diffuse>0.1 0.1 0.1 1</diffuse>
        </material>
      </visual>
    </link>

    <!-- Rueda derecha -->
    <link name="right_wheel">
      <pose>0 -0.7 0.18 1.57 0 0</pose>
      <inertial>
        <mass>0.5</mass>
        <inertia>
          <ixx>0.01</ixx><iyy>0.01</iyy><izz>0.01</izz>
        </inertia>
      </inertial>
      <collision name="collision">
        <geometry>
          <cylinder><radius>0.2</radius><length>0.2</length></cylinder>
        </geometry>
        <surface>
          <friction>
            <ode><mu>5.0</mu><mu2>5.0</mu2></ode>
          </friction>
        </surface>
      </collision>
      <visual name="visual">
        <geometry>
          <cylinder><radius>0.2</radius><length>0.2</length></cylinder>
        </geometry>
        <material>
          <ambient>0.1 0.1 0.1 1</ambient>
          <diffuse>0.1 0.1 0.1 1</diffuse>
        </material>
      </visual>
    </link>

    <!-- Caster TRASERO -->
    <link name="caster_rear">
      <pose>-0.6 0 0.1 0 0 0</pose>
      <inertial>
        <mass>0.1</mass>
        <inertia>
          <ixx>0.001</ixx><iyy>0.001</iyy><izz>0.001</izz>
        </inertia>
      </inertial>
      <collision name="collision">
        <geometry>
          <sphere><radius>0.1</radius></sphere>
        </geometry>
      </collision>
      <visual name="visual">
        <geometry>
          <sphere><radius>0.1</radius></sphere>
        </geometry>
        <material>
          <ambient>0.1 0.1 0.1 1</ambient>
          <diffuse>0.1 0.1 0.1 1</diffuse>
        </material>
      </visual>
    </link>

    <!-- Caster DELANTERO -->
    <link name="caster_front">
      <pose>0.6 0 0.1 0 0 0</pose>
      <inertial>
        <mass>0.1</mass>
        <inertia>
          <ixx>0.001</ixx><iyy>0.001</iyy><izz>0.001</izz>
        </inertia>
      </inertial>
      <collision name="collision">
        <geometry>
          <sphere><radius>0.1</radius></sphere>
        </geometry>
      </collision>
      <visual name="visual">
        <geometry>
          <sphere><radius>0.1</radius></sphere>
        </geometry>
        <material>
          <ambient>0.1 0.1 0.1 1</ambient>
          <diffuse>0.1 0.1 0.1 1</diffuse>
        </material>
      </visual>
    </link>

    <!-- Joints ruedas -->
    <joint name="left_wheel_joint" type="revolute">
      <parent>chassis</parent>
      <child>left_wheel</child>
      <axis>
        <xyz>0 0 1</xyz>
        <dynamics><damping>0.2</damping><friction>0.2</friction></dynamics>
      </axis>
    </joint>

    <joint name="right_wheel_joint" type="revolute">
      <parent>chassis</parent>
      <child>right_wheel</child>
      <axis>
        <xyz>0 0 1</xyz>
        <dynamics><damping>0.2</damping><friction>0.2</friction></dynamics>
      </axis>
    </joint>

    <!-- Joints casters (ball para rotar libre) -->
    <joint name="caster_rear_joint" type="ball">
      <parent>chassis</parent>
      <child>caster_rear</child>
    </joint>

    <joint name="caster_front_joint" type="ball">
      <parent>chassis</parent>
      <child>caster_front</child>
    </joint>

    <!-- Plugin DiffDrive -->
    <plugin
      filename="gz-sim-diff-drive-system"
      name="gz::sim::systems::DiffDrive">
      <left_joint>left_wheel_joint</left_joint>
      <right_joint>right_wheel_joint</right_joint>
      <wheel_separation>1.4</wheel_separation>
      <wheel_radius>0.2</wheel_radius>
      <topic>/model/bolitabot/cmd_vel</topic>
      <odom_topic>/model/bolitabot/odometry</odom_topic>
      <tf_topic>/model/bolitabot/tf</tf_topic>
    </plugin>

  </model>
</sdf>
