<?xml version="1.0" ?>
<sdf version="1.7">
  <world name="default">
    <model name="bolitabot">
      <pose>0 0 0.1 0 0 0</pose>

      <!-- Chasis -->
      <link name="chassis">
        <inertial>
          <mass>1.0</mass>
          <inertia>
            <ixx>0.1</ixx><ixy>0</ixy><ixz>0</ixz>
            <iyy>0.1</iyy><iyz>0</iyz><izz>0.1</izz>
          </inertia>
        </inertial>
        <visual name="visual">
          <geometry><box><size>0.4 0.3 0.1</size></box></geometry>
          <material>
            <ambient>1 0.5 0 1</ambient>
            <diffuse>1 0.5 0 1</diffuse>
          </material>
        </visual>
        <collision name="collision">
          <geometry><box><size>0.4 0.3 0.1</size></box></geometry>
        </collision>
      </link>

      <!-- Rueda izquierda -->
      <link name="left_wheel">
        <pose>0 0.17 0 -1.5707 0 0</pose>
        <inertial>
          <mass>0.2</mass>
          <inertia>
            <ixx>0.001</ixx><ixy>0</ixy><ixz>0</ixz>
            <iyy>0.001</iyy><iyz>0</iyz><izz>0.001</izz>
          </inertia>
        </inertial>
        <visual name="visual">
          <geometry><cylinder><radius>0.1</radius><length>0.05</length></cylinder></geometry>
          <material><ambient>0.2 0.2 0.2 1</ambient><diffuse>0.2 0.2 0.2 1</diffuse></material>
        </visual>
        <collision name="collision">
          <geometry><cylinder><radius>0.1</radius><length>0.05</length></cylinder></geometry>
        </collision>
      </link>

      <!-- Rueda derecha -->
      <link name="right_wheel">
        <pose>0 -0.17 0 -1.5707 0 0</pose>
        <inertial>
          <mass>0.2</mass>
          <inertia>
            <ixx>0.001</ixx><ixy>0</ixy><ixz>0</ixz>
            <iyy>0.001</iyy><iyz>0</iyz><izz>0.001</izz>
          </inertia>
        </inertial>
        <visual name="visual">
          <geometry><cylinder><radius>0.1</radius><length>0.05</length></cylinder></geometry>
          <material><ambient>0.2 0.2 0.2 1</ambient><diffuse>0.2 0.2 0.2 1</diffuse></material>
        </visual>
        <collision name="collision">
          <geometry><cylinder><radius>0.1</radius><length>0.05</length></cylinder></geometry>
        </collision>
      </link>

      <!-- Joint rueda izquierda -->
      <joint name="left_wheel_joint" type="revolute">
        <parent>chassis</parent>
        <child>left_wheel</child>
        <axis>
          <xyz>0 0 1</xyz>
          <limit><lower>-1e16</lower><upper>1e16</upper></limit>
        </axis>
      </joint>

      <!-- Joint rueda derecha -->
      <joint name="right_wheel_joint" type="revolute">
        <parent>chassis</parent>
        <child>right_wheel</child>
        <axis>
          <xyz>0 0 1</xyz>
          <limit><lower>-1e16</lower><upper>1e16</upper></limit>
        </axis>
      </joint>

      <!-- Plugin DiffDrive -->
      <plugin
        filename="gz-sim-diff-drive-system"
        name="gz::sim::systems::DiffDrive">
        <left_joint>left_wheel_joint</left_joint>
        <right_joint>right_wheel_joint</right_joint>
        <wheel_separation>0.34</wheel_separation>
        <wheel_radius>0.1</wheel_radius>
        <topic>/model/bolitabot/cmd_vel</topic>
        <odom_topic>/model/bolitabot/odometry</odom_topic>
        <tf_topic>/model/bolitabot/tf</tf_topic>
      </plugin>

    </model>
  </world>
</sdf>
